{
  DataVersion:3465,
  size:[5,3,4],
  palette:[
    {Name:"minecraft:blue_wool"},
    {Name:"minecraft:spruce_trapdoor"},
    {Name:"minecraft:lantern"}
  ],
  blocks:[
    {pos:[0,0,0],state:0},{pos:[0,0,3],state:0},{pos:[2,0,0],state:0},
    {pos:[2,0,3],state:0},{pos:[3,0,0],state:0},{pos:[3,0,3],state:0},
    {pos:[4,0,0],state:0},{pos:[4,0,1],state:0},{pos:[4,0,2],state:0},
    {pos:[4,0,3],state:0},{pos:[0,1,0],state:0},{pos:[0,1,3],state:0},
    {pos:[2,1,0],state:0},{pos:[2,1,3],state:0},{pos:[3,1,0],state:0},
    {pos:[3,1,2],state:2},{pos:[3,1,3],state:0},{pos:[4,1,0],state:0},
    {pos:[4,1,1],state:0},{pos:[4,1,2],state:0},{pos:[4,1,3],state:0},
    {pos:[0,2,0],state:1},{pos:[0,2,1],state:1},{pos:[0,2,2],state:1},
    {pos:[0,2,3],state:1},{pos:[1,2,0],state:1},{pos:[1,2,1],state:1},
    {pos:[1,2,2],state:1},{pos:[1,2,3],state:1},{pos:[2,2,0],state:1},
    {pos:[2,2,1],state:1},{pos:[2,2,2],state:1},{pos:[2,2,3],state:1},
    {pos:[3,2,0],state:1},{pos:[3,2,1],state:1},{pos:[3,2,2],state:1},
    {pos:[3,2,3],state:1},{pos:[4,2,0],state:1},{pos:[4,2,1],state:1},
    {pos:[4,2,2],state:1},{pos:[4,2,3],state:1}
  ],
  entities:[]
}
